Workbook

Sheet START HERE
B1: SHE LEFT THE CHAT
B2: MADRID MOVE TIMELINE BUILDER
B3: Tell it your target date. It builds your backwards planning checklist.
B5: STEP 1: ENTER YOUR DETAILS BELOW
B6: Yellow cells are yours to fill in. Everything else calculates automatically.
B8: Target Move Date | C8: The date you want to be living in Madrid.
B9: Visa Path | C9: Choose from dropdown →
B10: Applying From | C10: Inside Spain or US Consulate
B11: Your Name (optional) | C11: Personalizes the checklist tabs.
B13: STEP 2: GO TO YOUR VISA TAB
B14: Digital Nomad Visa (Inside Spain) | C14: Go to tab → DNV Inside Spain | D14: Each tab pulls your move date automatically.
B15: Digital Nomad Visa (US Consulate) | C15: Go to tab → DNV US Consulate | D15: Each tab pulls your move date automatically.
B16: Non-Lucrative Visa (US Consulate) | C16: Go to tab → Non-Lucrative Visa | D16: Each tab pulls your move date automatically.
B18: HOW THIS WORKBOOK WORKS
B19: • Enter your target move date in D8 once. | C19: Every deadline in every tab calculates from that single date.
B20: • Dates recalculate automatically. | C20: Change D8 and every milestone date updates instantly.
B21: • Override any date manually. | C21: Type directly into any deadline cell to fix a specific date.
B22: • Use the Status column. | C22: Mark tasks Done, In Progress, or Not Started as you work through them.
B23: • Add your own rows. | C23: Every tab has blank rows at the bottom for custom milestones.
B24: • Print any tab. | C24: Each checklist tab is print-ready on one or two pages.
B26: STATUS COLOR GUIDE (used across all tabs)
B27: Done | C27: Task completed
B28: In Progress | C28: Currently working on this
B29: Urgent / Overdue | C29: Deadline passed or critical
B30: Your Input Cells | C30: Yellow = fill these in
B31: Section Headers | C31: Phase and category dividers
B34: shelefthechat.com • Visa requirements and timelines change. Verify all deadlines with your immigration lawyer before acting on them.

Sheet DNV Inside Spain
B1: SHE LEFT THE CHAT • MADRID MOVE TIMELINE
B2: Digital Nomad Visa — Applying From Inside Spain
B3: Fastest route. 30-day response window. 3-year residency permit.
B5: TARGET MOVE DATE | D5: ='START HERE'!$D$8 -> 0 | E5: Change the date in START HERE tab → all deadlines update automatically
B7: ✓ | C7: TASK | D7: NOTES / DETAIL | E7: CALCULATED DEADLINE | F7: YOUR DATE OVERRIDE | G7: STATUS
B8: PHASE 1 • Get Clear Before You Commit • 12+ Months Before Move
B9: □ | C9: Book and complete a reconnaissance trip to Madrid | D9: Minimum 10 to 14 days. Rent an apartment, not a hotel. Visit in Oct, Nov, Mar, or Apr if possible. | E9: ='START HERE'!$D$8-365 -> -365 | G9: Not Started
B10: □ | C10: Confirm you qualify for the Digital Nomad Visa | D10: Requires min €2,849/month income (2026), employer operating 1+ years, max 20% income from Spanish clients. | E10: ='START HERE'!$D$8-365 -> -365 | G10: Not Started
B11: □ | C11: Consult a Spanish immigration lawyer based in Spain | D11: Book a 1-hour consultation. Verify your specific income type and employment situation qualifies before doing any paperwork. | E11: ='START HERE'!$D$8-350 -> -350 | G11: Not Started
B12: □ | C12: Decide on Madrid neighborhoods to target | D12: Use the Neighborhood Matcher at shelefthechat.com/resources. Shortlist 2 to 3 for apartment hunting on arrival. | E12: ='START HERE'!$D$8-340 -> -340 | G12: Not Started
B14: PHASE 2 • Research and Financial Setup • 9 to 12 Months Before Move
B15: □ | C15: Find and hire your Spanish immigration lawyer | D15: Ask for referrals in Madrid expat Facebook groups. Verify they have recent DNV experience. Budget €500 to €1,500. | E15: ='START HERE'!$D$8-300 -> -300 | G15: Not Started
B16: □ | C16: Open a Wise account and test an international transfer | D16: Do this before you need it. A small test transfer confirms the system works and you understand the process. | E16: ='START HERE'!$D$8-300 -> -300 | G16: Not Started
B17: □ | C17: Research real Madrid cost of living numbers | D17: Use the Cost of Living Calculator at shelefthechat.com/resources. Run your actual expenses against Madrid figures. | E17: ='START HERE'!$D$8-290 -> -290 | G17: Not Started
B18: □ | C18: Find a US expat tax specialist | D18: You still file US taxes living in Spain. Spain taxes you as a resident after 183 days. Find a specialist before year one ends. | E18: ='START HERE'!$D$8-280 -> -280 | G18: Not Started
B19: □ | C19: Build your 3-month relocation fund | D19: Separate from ongoing income. Budget additionally €5,000 to €8,000 for one-time arrival costs. | E19: ='START HERE'!$D$8-270 -> -270 | G19: Not Started
B20: □ | C20: Join 2 to 3 Madrid expat communities online | D20: Americans in Madrid, Madrid Expats, Women in Madrid on Facebook. These groups are where the real information lives. | E20: ='START HERE'!$D$8-270 -> -270 | G20: Not Started
B22: PHASE 3 • Document Preparation • 6 to 9 Months Before Move
B23: □ | C23: Check passport validity | D23: Must be valid for at least 1 year beyond your intended stay. Renew now if under 18 months remaining. | E23: ='START HERE'!$D$8-270 -> -270 | G23: Not Started
B24: □ | C24: Order FBI background check | D24: Federal level only. Allow 3 to 6 weeks processing time. Must be apostilled after receipt. | E24: ='START HERE'!$D$8-260 -> -260 | G24: Not Started
B25: □ | C25: Gather 3 to 6 months of bank statements | D25: Must show consistent deposits matching your declared income. UGE scrutinizes income consistency as of 2026. | E25: ='START HERE'!$D$8-250 -> -250 | G25: Not Started
B26: □ | C26: Obtain employment contract or client contracts | D26: Employer must have operated 1+ years. Contract must authorize remote work from Spain explicitly. | E26: ='START HERE'!$D$8-250 -> -250 | G26: Not Started
B27: □ | C27: Purchase Spain-approved private health insurance | D27: No copays, no deductibles, full Spain coverage, repatriation included. Sanitas, Adeslas, and Asisa are accepted. | E27: ='START HERE'!$D$8-240 -> -240 | G27: Not Started
B28: □ | C28: Apostille FBI background check | D28: US Department of State handles federal documents. Allow 4 to 8 weeks. Document must be under 6 months old at filing. | E28: ='START HERE'!$D$8-220 -> -220 | G28: Not Started
B29: □ | C29: Get certified Spanish translations of apostilled documents | D29: Must be done by a sworn translator. Your lawyer can recommend one. Do not use general translation services. | E29: ='START HERE'!$D$8-210 -> -210 | G29: Not Started
B30: □ | C30: Obtain EU-format passport photos | D30: 35mm x 45mm format. Not US standard size. Get new ones specifically for this application. | E30: ='START HERE'!$D$8-200 -> -200 | G30: Not Started
B32: PHASE 4 • Enter Spain and Apply In-Country • 3 to 6 Months Before Your Intended Residency Start
B33: □ | C33: Book flights and short-term furnished accommodation | D33: Book a furnished apartment for 4 to 8 weeks minimum. This is your base while applying and apartment hunting. | E33: ='START HERE'!$D$8-180 -> -180 | G33: Not Started
B34: □ | C34: Enter Spain on US passport before 90-day tourist limit expires | D34: Critical: you must apply before your legal entry period expires. US citizens get 90 days visa-free in Schengen. | E34: ='START HERE'!$D$8-90 -> -90 | G34: Not Started
B35: □ | C35: Submit DNV residency application to UGE through your lawyer | D35: UGE = Unidad de Grandes Empresas. Your lawyer submits on your behalf. Pay application fee €73.26 (2026). | E35: ='START HERE'!$D$8-85 -> -85 | G35: Not Started
B36: □ | C36: UGE 30-day response window begins | D36: UGE must respond within 30 days. If they do not, silencio administrativo positivo applies: approval is implied by law. | E36: ='START HERE'!$D$8-85 -> -85 | G36: Not Started
B37: □ | C37: Follow up with lawyer if no response after 30 days | D37: Implied approval does not produce a card automatically. Your lawyer follows up to get physical TIE documentation started. | E37: ='START HERE'!$D$8-55 -> -55 | G37: Not Started
B38: □ | C38: Register at ayuntamiento for empadronamiento | D38: Bring rental contract and passport. This certificate is required for TIE and many other official processes. | E38: ='START HERE'!$D$8-75 -> -75 | G38: Not Started
B40: PHASE 5 • Financial and Logistics Setup • 2 to 3 Months Before Move Date
B41: □ | C41: Open Spanish bank account | D41: Santander, BBVA, or CaixaBank. Bring passport, NIE, and empadronamiento certificate. Ask for cuenta de no residente if needed. | E41: ='START HERE'!$D$8-60 -> -60 | G41: Not Started
B42: □ | C42: Set up Bizum on Spanish account | D42: Linked to your phone number. Essential for splitting bills and paying small vendors. Wise and Revolut do not support Bizum. | E42: ='START HERE'!$D$8-55 -> -55 | G42: Not Started
B43: □ | C43: Source and confirm long-term apartment | D43: Search on Idealista and Fotocasa. Budget 1 to 2 months deposit. Confirm landlord will sign empadronamiento certificate. | E43: ='START HERE'!$D$8-45 -> -45 | G43: Not Started
B44: □ | C44: Set up mail forwarding from US address | D44: US Global Mail or Traveling Mailbox. You still need a US address for banking, tax, and family correspondence. | E44: ='START HERE'!$D$8-45 -> -45 | G44: Not Started
B45: □ | C45: Notify US bank and credit cards of international use | D45: Prevents fraud holds at the worst possible moment. Do this before you leave, not after a card is declined. | E45: ='START HERE'!$D$8-30 -> -30 | G45: Not Started
B46: □ | C46: Arrange 3 to 6 months of prescription medications | D46: With doctor's letter describing each medication's generic name. Confirm each is legal to bring into Spain. | E46: ='START HERE'!$D$8-30 -> -30 | G46: Not Started
...

Sheet DNV US Consulate
B1: SHE LEFT THE CHAT • MADRID MOVE TIMELINE
B2: Digital Nomad Visa — US Consulate Route
B3: Apply before leaving the US. Passport held during processing. Allow 4 to 8 months total.
B5: TARGET MOVE DATE | D5: ='START HERE'!$D$8 -> 0 | E5: Change the date in START HERE tab → all deadlines update automatically
B7: ✓ | C7: TASK | D7: NOTES / DETAIL | E7: CALCULATED DEADLINE | F7: YOUR DATE OVERRIDE | G7: STATUS
B8: PHASE 1 • Get Clear Before You Commit • 12+ Months Before Move
B9: □ | C9: Book and complete a reconnaissance trip to Madrid | D9: Minimum 10 to 14 days. Rent an apartment, not a hotel. Visit in Oct, Nov, Mar, or Apr if possible. | E9: ='START HERE'!$D$8-365 -> -365 | G9: Not Started
B10: □ | C10: Confirm you qualify for the Digital Nomad Visa | D10: Requires min €2,849/month income (2026), employer operating 1+ years, max 20% income from Spanish clients. | E10: ='START HERE'!$D$8-365 -> -365 | G10: Not Started
B11: □ | C11: Consult an immigration lawyer or gestor | D11: Verify your specific situation qualifies. Budget €500 to €1,500 for application assistance. | E11: ='START HERE'!$D$8-350 -> -350 | G11: Not Started
B12: □ | C12: Check appointment availability at your Spanish Consulate | D12: Critical first step. Some consulates have 2-week waits, others 3 months. Your appointment date anchors everything. | E12: ='START HERE'!$D$8-340 -> -340 | G12: Not Started
B14: PHASE 2 • Research and Financial Setup • 9 to 12 Months Before Move
B15: □ | C15: Open a Wise account and test an international transfer | D15: Do this before you need it urgently. | E15: ='START HERE'!$D$8-300 -> -300 | G15: Not Started
B16: □ | C16: Build your 3-month relocation fund | D16: Separate from ongoing income. Budget €5,000 to €8,000 for arrival costs. | E16: ='START HERE'!$D$8-280 -> -280 | G16: Not Started
B17: □ | C17: Find a US expat tax specialist | D17: Spain taxes you as resident after 183 days. You still file US taxes regardless of where you live. | E17: ='START HERE'!$D$8-280 -> -280 | G17: Not Started
B18: □ | C18: Research real Madrid cost of living numbers | D18: Use the Cost of Living Calculator at shelefthechat.com/resources. | E18: ='START HERE'!$D$8-270 -> -270 | G18: Not Started
B20: PHASE 3 • Document Preparation • 6 to 9 Months Before Move
B21: □ | C21: Check passport validity | D21: Must be valid 1+ year beyond stay. Renew immediately if under 18 months remaining. | E21: ='START HERE'!$D$8-270 -> -270 | G21: Not Started
B22: □ | C22: Order FBI background check | D22: Federal level only. Allow 3 to 6 weeks. Must be apostilled. Under 6 months old at time of filing. | E22: ='START HERE'!$D$8-260 -> -260 | G22: Not Started
B23: □ | C23: Gather 3 to 6 months of bank statements | D23: Must show consistent income deposits matching your declared amount. | E23: ='START HERE'!$D$8-250 -> -250 | G23: Not Started
B24: □ | C24: Obtain employment contract proving remote authorization | D24: Employer must have operated 1+ years. Contract must explicitly authorize working from Spain. | E24: ='START HERE'!$D$8-245 -> -245 | G24: Not Started
B25: □ | C25: Purchase Spain-approved private health insurance | D25: No copays, full Spain coverage. Sanitas, Adeslas, and Asisa are accepted providers. | E25: ='START HERE'!$D$8-240 -> -240 | G25: Not Started
B26: □ | C26: Apostille FBI background check via US Dept of State | D26: Allow 4 to 8 weeks. Expedited processing available. Document cannot be older than 6 months at consulate appointment. | E26: ='START HERE'!$D$8-220 -> -220 | G26: Not Started
B27: □ | C27: Get certified Spanish translations of all apostilled documents | D27: Must be a sworn translator. Your gestor or lawyer can recommend one. | E27: ='START HERE'!$D$8-200 -> -200 | G27: Not Started
B28: □ | C28: Obtain EU-format passport photos | D28: 35mm x 45mm. Not US standard size. | E28: ='START HERE'!$D$8-195 -> -195 | G28: Not Started
B30: PHASE 4 • Consulate Application • 4 to 6 Months Before Move
B31: □ | C31: Book consulate visa appointment | D31: At the Spanish Consulate for your US state of residence. Book as early as available. This date drives your full timeline. | E31: ='START HERE'!$D$8-180 -> -180 | G31: Not Started
B32: □ | C32: Complete visa application form with lawyer or gestor | D32: Tasa 790-038 government fee: €73.26 (2026). Your gestor assembles the full application package. | E32: ='START HERE'!$D$8-160 -> -160 | G32: Not Started
B33: □ | C33: Attend consulate appointment and submit application | D33: Bring originals and copies of everything. Passport surrendered at appointment and held during processing. | E33: ='START HERE'!$D$8-150 -> -150 | G33: Not Started
B34: □ | C34: Consulate processing period (up to 8 months total) | D34: Processing times vary widely by consulate. Plan for 2 to 6 months. You cannot travel internationally without your passport during this time. | E34: ='START HERE'!$D$8-150 -> -150 | G34: Not Started
B35: □ | C35: Collect visa from consulate once approved | D35: You receive a 1-year visa sticker in your passport. This gets converted to a 3-year TIE after arrival. | E35: ='START HERE'!$D$8-30 -> -30 | G35: Not Started
B37: PHASE 5 • Pre-Departure Logistics • 1 to 3 Months Before Move
B38: □ | C38: Book short-term furnished accommodation for first 4 to 8 weeks | D38: Do not sign a long-term lease before spending time in the neighborhood. Short-term first. | E38: ='START HERE'!$D$8-60 -> -60 | G38: Not Started
B39: □ | C39: Set up mail forwarding from US address | D39: US Global Mail or Traveling Mailbox. | E39: ='START HERE'!$D$8-45 -> -45 | G39: Not Started
B40: □ | C40: Notify US bank and credit cards of international use | D40: Prevents fraud holds. Do before departure. | E40: ='START HERE'!$D$8-30 -> -30 | G40: Not Started
B41: □ | C41: Arrange 3 to 6 months of prescription medications | D41: With doctor's letter. Confirm each medication is legal to bring into Spain. | E41: ='START HERE'!$D$8-30 -> -30 | G41: Not Started
B42: □ | C42: Pack all documents in carry-on bag | D42: Never in checked luggage. Originals and copies of everything. | E42: ='START HERE'!$D$8-7 -> -7 | G42: Not Started
B44: PHASE 6 • First 90 Days in Madrid • After You Land
B45: □ | C45: Buy local SIM card on arrival day | D45: Movistar, Vodafone, or Orange. Spanish number required for almost every official process. | E45: ='START HERE'!$D$8+0 -> 0 | G45: Not Started
B46: □ | C46: Register at ayuntamiento for empadronamiento | D46: Within first 2 weeks. Bring rental contract and passport. | E46: ='START HERE'!$D$8+7 -> 7 | G46: Not Started
B47: □ | C47: Book TIE appointment to convert visa to residency card | D47: Your 1-year consulate visa must be converted to a TIE within 30 days of arrival. Book immediately. | E47: ='START HERE'!$D$8+1 -> 1 | G47: Not Started
...

Sheet Non-Lucrative Visa
B1: SHE LEFT THE CHAT • MADRID MOVE TIMELINE
B2: Non-Lucrative Visa — US Consulate Route
B3: For passive income, pensions, and savings. No remote work permitted on this visa.
B5: TARGET MOVE DATE | D5: ='START HERE'!$D$8 -> 0 | E5: Change the date in START HERE tab → all deadlines update automatically
B7: ✓ | C7: TASK | D7: NOTES / DETAIL | E7: CALCULATED DEADLINE | F7: YOUR DATE OVERRIDE | G7: STATUS
B8: PHASE 1 • Confirm Eligibility and Make the Decision • 12+ Months Before Move
B9: □ | C9: Confirm you qualify for the Non-Lucrative Visa | D9: Requires approx €28,800/year passive income (2026, verify annually). You CANNOT work remotely on this visa. | E9: ='START HERE'!$D$8-365 -> -365 | G9: Not Started
B10: □ | C10: Verify your income type qualifies as passive | D10: Pension, Social Security, investment income, savings drawdown, rental income. Active remote work disqualifies you. | E10: ='START HERE'!$D$8-365 -> -365 | G10: Not Started
B11: □ | C11: Consult an immigration lawyer to confirm NLV is right for you | D11: This is the most common visa mistake: applying for NLV while intending to do any remote work. Clarify before starting. | E11: ='START HERE'!$D$8-350 -> -350 | G11: Not Started
B12: □ | C12: Book and complete a reconnaissance trip to Madrid | D12: Minimum 10 to 14 days. Rent an apartment, not a hotel. Non-summer months give a more realistic picture. | E12: ='START HERE'!$D$8-340 -> -340 | G12: Not Started
B13: □ | C13: Check consulate appointment availability immediately | D13: NLV processing through US consulates can take 4 to 6 months. Your appointment date is the most important deadline. | E13: ='START HERE'!$D$8-330 -> -330 | G13: Not Started
B15: PHASE 2 • Research and Financial Preparation • 9 to 12 Months Before Move
B16: □ | C16: Open a Wise account and test international transfers | D16: Best exchange rates for regular transfers between US and Spanish accounts. | E16: ='START HERE'!$D$8-300 -> -300 | G16: Not Started
B17: □ | C17: Build your relocation fund | D17: 3 months liquid expenses minimum plus €5,000 to €8,000 for one-time arrival costs. | E17: ='START HERE'!$D$8-290 -> -290 | G17: Not Started
B18: □ | C18: Find a US expat tax specialist | D18: Spain taxes you as resident after 183 days on worldwide income. FBAR required if foreign accounts exceed $10,000. | E18: ='START HERE'!$D$8-280 -> -280 | G18: Not Started
B19: □ | C19: Research real Madrid cost of living | D19: Use the Cost of Living Calculator at shelefthechat.com/resources. Run your actual income against Madrid figures. | E19: ='START HERE'!$D$8-270 -> -270 | G19: Not Started
B20: □ | C20: Understand the NLV income verification requirements | D20: You need to show the full year's income threshold, not just a recent month. Gather documentation for a full 12-month period. | E20: ='START HERE'!$D$8-260 -> -260 | G20: Not Started
B22: PHASE 3 • Document Preparation • 6 to 9 Months Before Move
B23: □ | C23: Check passport validity | D23: Must be valid 1+ year beyond stay. Renew immediately if under 18 months. | E23: ='START HERE'!$D$8-270 -> -270 | G23: Not Started
B24: □ | C24: Order FBI background check | D24: Federal level only. Allow 3 to 6 weeks. Must be apostilled. Under 6 months old at consulate appointment. | E24: ='START HERE'!$D$8-260 -> -260 | G24: Not Started
B25: □ | C25: Gather proof of passive income for full year | D25: Pension statements, Social Security award letter, investment account statements, bank statements. All 12 months. | E25: ='START HERE'!$D$8-250 -> -250 | G25: Not Started
B26: □ | C26: Purchase Spain-approved private health insurance | D26: No copays, no deductibles, full Spain coverage. Sanitas, Adeslas, Asisa accepted. Required for NLV. | E26: ='START HERE'!$D$8-240 -> -240 | G26: Not Started
B27: □ | C27: Apostille FBI background check | D27: US Department of State. Allow 4 to 8 weeks. The 6-month validity clock starts at issuance, not apostille. | E27: ='START HERE'!$D$8-220 -> -220 | G27: Not Started
B28: □ | C28: Apostille birth certificate if required | D28: Some NLV applications require it. Confirm with your consulate. Secretary of State for state-issued documents. | E28: ='START HERE'!$D$8-210 -> -210 | G28: Not Started
B29: □ | C29: Get certified Spanish translations of all apostilled documents | D29: Must be sworn translator. Not Google Translate. Not a bilingual friend. | E29: ='START HERE'!$D$8-200 -> -200 | G29: Not Started
B30: □ | C30: Obtain EU-format passport photos | D30: 35mm x 45mm. Different from US standard. Get new ones specifically. | E30: ='START HERE'!$D$8-195 -> -195 | G30: Not Started
B31: □ | C31: Complete NLV application form with gestor | D31: Tasa 790-052 government fee applies. Your gestor or lawyer assembles the full package. | E31: ='START HERE'!$D$8-180 -> -180 | G31: Not Started
B33: PHASE 4 • Consulate Application • 4 to 6 Months Before Move
B34: □ | C34: Book consulate visa appointment | D34: At the Spanish Consulate for your US state of residence. Book the earliest available slot. | E34: ='START HERE'!$D$8-180 -> -180 | G34: Not Started
B35: □ | C35: Attend consulate appointment and submit NLV application | D35: Bring originals and 2 copies of everything. Passport surrendered and held during processing. | E35: ='START HERE'!$D$8-150 -> -150 | G35: Not Started
B36: □ | C36: Processing period (4 to 6 weeks typical) | D36: NLV processing is typically faster than DNV. Cannot travel internationally while passport is held. | E36: ='START HERE'!$D$8-150 -> -150 | G36: Not Started
B37: □ | C37: Collect NLV visa from consulate | D37: You receive a 1-year visa. This is renewed annually in Spain and converts to long-term residency after 5 years. | E37: ='START HERE'!$D$8-30 -> -30 | G37: Not Started
B39: PHASE 5 • Pre-Departure Logistics • 1 to 3 Months Before Move
B40: □ | C40: Book short-term furnished accommodation for first 4 to 8 weeks | D40: Do not sign long-term lease before visiting neighborhoods. Short-term first. | E40: ='START HERE'!$D$8-60 -> -60 | G40: Not Started
B41: □ | C41: Set up mail forwarding | D41: US Global Mail or Traveling Mailbox. You need a US address for banking and tax correspondence. | E41: ='START HERE'!$D$8-45 -> -45 | G41: Not Started
B42: □ | C42: Notify US bank and credit cards of international use | D42: Prevents fraud holds. | E42: ='START HERE'!$D$8-30 -> -30 | G42: Not Started
B43: □ | C43: Arrange 3 to 6 months of prescription medications | D43: With doctor's letter listing generic names. Confirm legal to bring into Spain. | E43: ='START HERE'!$D$8-30 -> -30 | G43: Not Started
B44: □ | C44: Decide what to bring, ship, or sell | D44: Spain runs 220V/50Hz. US appliances need converters or replacement. Price shipping honestly. | E44: ='START HERE'!$D$8-21 -> -21 | G44: Not Started
B45: □ | C45: Pack all documents in carry-on bag | D45: Originals and copies. Never in checked luggage. | E45: ='START HERE'!$D$8-7 -> -7 | G45: Not Started
B47: PHASE 6 • First 90 Days in Madrid • After You Land
...

Sheet Residency Day Tracker
B1: SHE LEFT THE CHAT • RESIDENCY DAY TRACKER
B2: Track Your Days in Spain Toward Permanent Residency
B3: Long-term residency after 5 years requires 183+ days per year IN Spain. Extended absences reset your clock. Track from day one.
B5: THE RULE YOU NEED TO KNOW
B6: 183+ days per year in Spain | C6: Required for each of the 5 years leading to permanent residency.
B7: No single absence over 6 consecutive months | C7: A trip home that runs long can jeopardize your residency path.
B8: Total absences tracked cumulatively | C8: It is not just about single trips. The annual total matters.
B9: Clock can restart if requirements are not met | C9: Missing a year means potentially starting your 5-year count again.
B11: ANNUAL DAYS IN SPAIN TRACKER
B12: YEAR | C12: Days IN Spain | D12: Days Outside Spain | E12: Meets 183-Day Rule? | F12: Notes
B13: Year 1 | D13: =IF(C13="","",365-C13) | E13: =IF(C13="","",IF(C13>=183,"YES ✔","NO ✖ — Short by "&(183-C13)&" days"))
B14: Year 2 | D14: =IF(C14="","",365-C14) | E14: =IF(C14="","",IF(C14>=183,"YES ✔","NO ✖ — Short by "&(183-C14)&" days"))
B15: Year 3 | D15: =IF(C15="","",365-C15) | E15: =IF(C15="","",IF(C15>=183,"YES ✔","NO ✖ — Short by "&(183-C15)&" days"))
B16: Year 4 | D16: =IF(C16="","",365-C16) | E16: =IF(C16="","",IF(C16>=183,"YES ✔","NO ✖ — Short by "&(183-C16)&" days"))
B17: Year 5 | D17: =IF(C17="","",365-C17) | E17: =IF(C17="","",IF(C17>=183,"YES ✔","NO ✖ — Short by "&(183-C17)&" days"))
B18: 5-Year Total | C18: =SUM(C13:C17) -> 0 | D18: =SUM(D13:D17) -> 0 | E18: =IF(C18="","",IF(C18>=915,"On track for permanent residency ✔","Not yet on track — "&(915-C18)&" more days needed")) -> Not yet on track — 915 more days needed
B20: shelefthechat.com • This tracker is a personal planning tool. Residency rules change. Verify requirements with your immigration lawyer.
